Workbook

Sheet Calendrier
A1: FICTIF : document de test. Unifood est une entreprise réelle ; personnes, budget et résultats inventés. Rien n'est publié ni programmé.
A2: Calendrier éditorial novembre 2026 : Facebook, Instagram, TikTok (Rio Pop, TOMY, Unifood). Version 2 du 19/10/2026, à valider par Mariam Koné (FICTIF).
E3: Framboise #E50046 | F3: Jaune or #FAB900 | G3: Encre #2B1B22 | H3: Orange #F07E26 | I3: Violet #A4539B | J3: Vert #67B32E | K3: Bleu ciel #61C3D9
A4: N° | B4: Date | C4: Jour | D4: Heure | E4: Réseau | F4: Compte | G4: Format | H4: Gamme | I4: Cible | J4: Pilier | K4: Étage | L4: Sujet | M4: Accroche A | N4: Accroche B (à tester) | O4: Légende prête | P4: Hashtags | Q4: Appel à l'action | R4: Visuel | S4: Lien du visuel (Drive) | T4: Responsable | U4: Statut
A5: 1 | B5: 46328 | C5: lundi 2 nov. | D5: 18:00 | E5: TikTok | F5: TOMY (nouveau compte) | G5: Vidéo 15 s | H5: Toutes | I5: 13 à 17 ans et jeunes adultes | J5: Couleurs et fun | K5: TOFU, se faire connaître | L5: Ouverture du compte : toute la famille TOMY en 15 secondes | M5: TOMY arrive sur TikTok, et ça va colorer ton fil ! | N5: Rio Pop, Super Mint, Gnamakou... On est là ! | O5: TOMY arrive sur TikTok, et ça va colorer ton fil ! 🍭❄️🔥 Rio Pop, Super Mint, Tempo, Super Gnamakou : toute la bande est là. Abonne-toi, la suite arrive vite 👀 | P5: #TOMY #RioPop #Abidjan #225 | Q5: Abonne-toi | R5: visuels/post01_famille.jpg | S5: =HYPERLINK("https://drive.google.com/file/d/1wO-GmpCCdd1HYKsbqDRpJNEBhhCntGm2/view?usp=drivesdk","Voir le visuel 1") | T5: Koffi (montage), Prisca Yao (publication) | U5: à valider
A6: 2 | B6: 46329 | C6: mardi 3 nov. | D6: 12:30 | E6: Facebook | F6: Rio Pop @RioPop225 | G6: Carrousel 5 images | H6: Rio Pop | I6: Parents 25 à 45 ans | J6: Couleurs et fun | K6: MOFU, faire considérer | L6: Les parfums Rio Pop, un par image | M6: Mangue, fraise, passion, cola... Chez vous, c'est quel parfum ? | N6: 5 parfums, 1 seule question : le vôtre ? | O6: Mangue, fraise, passion, cola, mix fruits... Chez vous, c'est quel parfum qui part en premier ? 🍭 Dites-le en commentaire, on compte les votes vendredi ! | P6: #RioPop #RienNteStop #Abidjan | Q6: Votez en commentaire | R6: visuels/post02_parfums.jpg | S6: =HYPERLINK("https://drive.google.com/file/d/1lfqJX7bLeKk2mmtlypTaXgzTOBE_PRIl/view?usp=drivesdk","Voir le visuel 2") | T6: Koffi (visuels), Prisca Yao | U6: à valider
A7: 3 | B7: 46329 | C7: mardi 3 nov. | D7: 19:00 | E7: Instagram | F7: Rio Pop (nouveau compte) | G7: Post carré | H7: Rio Pop | I7: Parents et ados 13 à 17 ans | J7: Couleurs et fun | K7: TOFU, se faire connaître | L7: Premier post du compte Instagram Rio Pop | M7: Rio Pop débarque sur Instagram 🎉 | N7: Les sucettes qui colorent vos journées, maintenant ici. | O7: Rio Pop débarque sur Instagram 🎉 Les sucettes qui colorent vos journées, avec un cœur chewing-gum dedans. Abonnez-vous pour les idées de fêtes, les défis et les nouveautés 🍭 | P7: #RioPop #RienNteStop #TOMY #Abidjan #CôteDIvoire #225 #Babi #Sucette #Bonbon | Q7: Abonnez-vous | R7: visuels/post03_sachet48_rouge.jpg | S7: =HYPERLINK("https://drive.google.com/file/d/1oKR3HOheFwFKyjhlVx0IIvmCiD3BF1YO/view?usp=drivesdk","Voir le visuel 3") | T7: Prisca Yao | U7: à valider
A8: 4 | B8: 46330 | C8: mercredi 4 nov. | D8: 18:00 | E8: TikTok | F8: TOMY | G8: Vidéo 20 s (défi) | H8: Rio Pop | I8: 13 à 17 ans | J8: Défi Montre ta langue | K8: TOFU, se faire connaître | L8: Lancement du défi « Montre ta langue Rio Pop » (Tongue Painter) | M8: Montre ta langue, on devine ton parfum 👅 | N8: Ta langue est de quelle couleur ce soir ? | O8: Montre ta langue, on devine ton parfum 👅🎨 Rio Pop Tongue Painter : la sucette qui colore la langue. Fais le défi, mets #MontreTaLangueRioPop et identifie-nous ! | P8: #MontreTaLangueRioPop #RioPop #TOMY #225 | Q8: Fais le défi | R8: visuels/post04_langue.jpg | S8: =HYPERLINK("https://drive.google.com/file/d/1nfL9_7ZvtERBiY-HVTSQbY2K2lqGPujN/view?usp=drivesdk","Voir le visuel 4") | T8: Koffi (tournage avec l'équipe, 13 ans et plus seulement) | U8: à valider
A9: 5 | B9: 46331 | C9: jeudi 5 nov. | D9: 18:00 | E9: TikTok | F9: TOMY | G9: Sketch 25 s | H9: Super Mint | I9: Adultes 20 à 45 ans | J9: Fraîcheur de la route | K9: TOFU, se faire connaître | L9: Sketch « Le gbaka bondé » : le voisin qui a mangé l'attiéké poisson | M9: Dans le gbaka à 7 h, il te faut un Super Mint 😮‍💨 | N9: Ton voisin de gbaka a mangé quoi ce matin ? | O9: Dans le gbaka à 7 h, il te faut un Super Mint 😮‍💨❄️ Ça glace fort ! Tague le collègue qui en a besoin 😂 | P9: #SuperMint #TOMY #Abidjan #Gbaka | Q9: Tague un collègue | R9: visuels/post05_supermint_video.jpg | S9: =HYPERLINK("https://drive.google.com/file/d/1M9uA1-cTPxx_o0CXkiy4IinUK4pgsAJF/view?usp=drivesdk","Voir le visuel 5") | T9: Koffi (sketch), Fatima (texte) | U9: à valider
A10: 6 | B10: 46332 | C10: vendredi 6 nov. | D10: 12:30 | E10: Facebook | F10: Rio Pop @RioPop225 | G10: Post photo | H10: Rio Pop | I10: Parents 25 à 45 ans | J10: Fêtes et anniversaires | K10: MOFU, faire considérer | L10: Idées goûter n°1 : la boîte à goûter du vendredi | M10: Vendredi, la boîte à goûter a droit à sa petite surprise 🍭 | N10: Le goûter du vendredi, c'est sacré ! | O10: Vendredi, la boîte à goûter a droit à sa petite surprise 🍭 Une sucette Rio Pop glissée à côté du goûter, et la semaine finit en couleur. Et chez vous, c'est quoi la surprise du vendredi ? 👇 | P10: #RioPop #RienNteStop #Goûter | Q10: Racontez en commentaire | R10: visuels/post06_gouter.jpg | S10: =HYPERLINK("https://drive.google.com/file/d/1ius3OsXMrFDSV9tqH-sNcICCzwmdwY8Z/view?usp=drivesdk","Voir le visuel 6") | T10: Koffi, Prisca Yao | U10: à valider
A11: 7 | B11: 46332 | C11: vendredi 6 nov. | D11: 19:00 | E11: Instagram | F11: Rio Pop | G11: Reel (reprise TikTok) | H11: Rio Pop | I11: Ados 13 à 17 ans | J11: Défi Montre ta langue | K11: TOFU, se faire connaître | L11: Reprise du défi « Montre ta langue » | M11: Langue bleue, rouge ou violette ? 👅 | N11: Le défi qui colore Babi. | O11: Langue bleue, rouge ou violette ? 👅🎨 Le défi #MontreTaLangueRioPop est lancé. Montre-nous la tienne en story et identifie @riopop ! | P11: #MontreTaLangueRioPop #RioPop #RienNteStop #TOMY #Abidjan #225 #Babi #Défi #Sucette | Q11: Fais le défi en story | R11: visuels/post07_langue.jpg | S11: =HYPERLINK("https://drive.google.com/file/d/1RWb0RwuZb7DtJP5-zkc5xU-497MwbopH/view?usp=drivesdk","Voir le visuel 7") | T11: Prisca Yao | U11: à valider
A12: 8 | B12: 46333 | C12: samedi 7 nov. | D12: 18:00 | E12: TikTok | F12: TOMY | G12: Sketch 25 s | H12: Super Gnamakou | I12: Adultes 20 à 45 ans | J12: Fraîcheur de la route | K12: TOFU, se faire connaître | L12: Sketch « Après le garba » : Super Gnamakou au gingembre | M12: Garba fini, Gnamakou servi 🔥 | N12: Après le garba, il faut le gingembre ! | O12: Garba fini, Gnamakou servi 🔥 Super Gnamakou au gingembre : ça chauffe grave ! Toi, c'est menthe ou gingembre après manger ? 👇 | P12: #SuperGnamakou #TOMY #Garba #225 | Q12: Réponds en commentaire | R12: visuels/post08_gnamakou_video.jpg | S12: =HYPERLINK("https://drive.google.com/file/d/1ARbtwNzA54HqnbkuegiCfxmVWzWbq7-V/view?usp=drivesdk","Voir le visuel 8") | T12: Koffi, Fatima | U12: à valider
A13: 9 | B13: 46333 | C13: samedi 7 nov. | D13: 12:30 | E13: Facebook | F13: Unifood | G13: Vidéo (reprise TikTok) | H13: Super Mint | I13: Adultes 20 à 45 ans | J13: Fraîcheur de la route | K13: TOFU, se faire connaître | L13: Reprise du sketch « Le gbaka bondé » | M13: On a tous connu ce voisin de gbaka 😅 | N13: 7 h du matin, le gbaka, et ce voisin... | O13: On a tous connu ce voisin de gbaka 😅 Heureusement, il y a Super Mint. Ça glace fort ! ❄️ Partagez à celui qui doit voir ça 😂 | P13: #SuperMint #TOMY | Q13: Partagez | R13: visuels/post09_supermint_video.jpg | S13: =HYPERLINK("https://drive.google.com/file/d/1G24sTkVyLpiTMNdD5D1N0LqQ4fyhwIZR/view?usp=drivesdk","Voir le visuel 9") | T13: Prisca Yao | U13: à valider
A14: 10 | B14: 46334 | C14: dimanche 8 nov. | D14: 16:00 | E14: Facebook | F14: Rio Pop @RioPop225 | G14: Post photo | H14: Rio Pop | I14: Parents 25 à 45 ans | J14: Fêtes et anniversaires | K14: MOFU, faire considérer | L14: Déco de fête n°1 : le bouquet de sucettes | M14: Le centre de table qui disparaît en 5 minutes 🎈 | N14: Un bouquet qui se mange ? Oui ! | O14: Le centre de table qui disparaît en 5 minutes 🎈🍭 Prenez un pot, du papier coloré, et plantez-y vos sucettes Rio Pop par couleur. Les enfants se servent à la fin de la fête. Enregistrez l'idée pour le prochain anniversaire 📌 | P14: #RioPop #Anniversaire #DécoDeFête | Q14: Enregistrez l'idée | R14: visuels/post10_bouquet.jpg | S14: =HYPERLINK("https://drive.google.com/file/d/1b_2Iwjcx2WvD4vRqsu4bgFZ3unnWdTgy/view?usp=drivesdk","Voir le visuel 10") | T14: Koffi (photo), Prisca Yao | U14: à valider
A15: 11 | B15: 46334 | C15: dimanche 8 nov. | D15: 19:00 | E15: Instagram | F15: Rio Pop | G15: Post carré | H15: Rio Pop | I15: Parents 25 à 45 ans | J15: Fêtes et anniversaires | K15: MOFU, faire considérer | L15: Reprise du bouquet de sucettes | M15: Le bouquet qui fait la fête 🎈 | N15: L'idée déco à enregistrer. | O15: Le bouquet qui fait la fête 🎈🍭 1 pot, du papier coloré, des sucettes Rio Pop rangées par couleur. Les enfants se servent en partant. 📌 Enregistrez pour le prochain anniversaire ! | P15: #RioPop #RienNteStop #Anniversaire #DécoAnniversaire #FêteEnfant #Abidjan #225 #Babi #IdéeDéco | Q15: Enregistrez | R15: visuels/post11_bouquet.jpg | S15: =HYPERLINK("https://drive.google.com/file/d/1n81fEZ8k5wI5-3H3DGsqPpdT13FTm5Tr/view?usp=drivesdk","Voir le visuel 11") | T15: Prisca Yao | U15: à valider
A16: 12 | B16: 46335 | C16: lundi 9 nov. | D16: 18:00 | E16: TikTok | F16: TOMY | G16: Vidéo 15 s | H16: Rio Pop | I16: 13 à 17 ans | J16: Défi Montre ta langue | K16: TOFU, se faire connaître | L16: Meilleures langues de la semaine 1 (reprises des abonnés, avec leur accord) | M16: Vous avez fait le défi, on a vu vos langues 😂 | N16: Top 3 des langues les plus colorées ! | O16: Vous avez fait le défi, on a vu vos langues 😂👅 Voici notre top 3 de la semaine. La tienne est la prochaine ? #MontreTaLangueRioPop | P16: #MontreTaLangueRioPop #RioPop #TOMY #225 | Q16: Fais le défi | R16: visuels/post12_langue.jpg | S16: =HYPERLINK("https://drive.google.com/file/d/1PNPAKbzm9IufeKN4QtfpIg5A7UbQbpro/view?usp=drivesdk","Voir le visuel 12") | T16: Prisca Yao (accord écrit de chaque abonné repris) | U16: à valider
A17: 13 | B17: 46336 | C17: mardi 10 nov. | D17: 12:30 | E17: Facebook | F17: Rio Pop @RioPop225 | G17: Post photo | H17: Rio Pop | I17: Parents 25 à 45 ans | J17: Couleurs et fun | K17: MOFU, faire considérer | L17: Résultat du vote des parfums | M17: Vous avez voté : le parfum n°1, c'est... ⟦résultat du vote⟧ ! | N17: Le verdict est tombé 🏆 | O17: Vous avez voté, et le parfum n°1 chez vous c'est... ⟦résultat du vote du 3 novembre⟧ ! 🏆🍭 Merci pour vos ⟦nombre⟧ commentaires. Votre parfum n'a pas gagné ? Défendez-le ici 👇 | P17: #RioPop #RienNteStop | Q17: Commentez | R17: visuels/post13_parfums.jpg | S17: =HYPERLINK("https://drive.google.com/file/d/1StJe-UQlkHXWSvS_2pAecP14bZiMGycR/view?usp=drivesdk","Voir le visuel 13") | T17: Prisca Yao | U17: à compléter le jour même
A18: 14 | B18: 46336 | C18: mardi 10 nov. | D18: 19:00 | E18: Instagram | F18: Rio Pop | G18: Story sondage + post | H18: Rio Pop | I18: Ados 13 à 17 ans | J18: Couleurs et fun | K18: MOFU, faire considérer | L18: Sondage « Mangue ou passion ? » | M18: Mangue ou passion ? Tu as 24 h pour choisir 🥭 | N18: Un seul parfum pour toute la semaine : lequel ? | O18: Mangue ou passion ? Tu as 24 h pour choisir 🥭💛 Vote dans notre story ! | P18: #RioPop #RienNteStop #TOMY #Abidjan #225 #Babi #Sondage #Sucette | Q18: Vote en story | R18: visuels/post14_mangue_passion.jpg | S18: =HYPERLINK("https://drive.google.com/file/d/1od4CxR2jpilD-3gLvOKNCiOibREfvjX-/view?usp=drivesdk","Voir le visuel 14") | T18: Prisca Yao | U18: à valider
A19: 15 | B19: 46337 | C19: mercredi 11 nov. | D19: 18:00 | E19: TikTok | F19: TOMY | G19: Vidéo 20 s | H19: Rio Pop Ice Cream | I19: 13 à 17 ans | J19: Couleurs et fun | K19: TOFU, se faire connaître | L19: ASMR déballage Rio Pop Ice Cream | M19: Le bruit du papier Rio Pop Ice Cream 🔊 | N19: Rio Pop Ice Cream, tu connais ? | O19: Le bruit du papier, puis le goût Ice Cream 🔊🍦 Rio Pop Ice Cream, tu as déjà goûté ? | P19: #RioPop #ASMR #TOMY #225 | Q19: Dis-nous en commentaire | R19: visuels/post15_icecream.jpg | S19: =HYPERLINK("https://drive.google.com/file/d/1iPbCxM5Y5as7it3rZ7Ilz4OkGInDDwlc/view?usp=drivesdk","Voir le visuel 15") | T19: Koffi | U19: à valider
A20: 16 | B20: 46338 | C20: jeudi 12 nov. | D20: 12:30 | E20: Facebook | F20: Rio Pop @RioPop225 | G20: Post audio + visuel | H20: Rio Pop | I20: Parents 25 à 45 ans | J20: Couleurs et fun | K20: TOFU, se faire connaître | L20: « Vous nous avez entendus à la radio ? » (spot en cours depuis le 9 nov.) | M20: Vous avez entendu Rio Pop à la radio ? 📻 | N20: Le spot que vos enfants chantent déjà... | O20: Vous avez entendu Rio Pop à la radio cette semaine ? 📻🍭 Rio Pop, rien n'te stop ! Écoutez le spot ici et dites-nous sur quelle radio vous l'avez entendu. | P20: #RioPop #RienNteStop | Q20: Dites-nous en commentaire | R20: visuels/post16_radio.jpg | S20: =HYPERLINK("https://drive.google.com/file/d/1Y3VJRBtFolojd-g9BzBgpKjTDVV5zVVi/view?usp=drivesdk","Voir le visuel 16") | T20: Prisca Yao (après diffusion confirmée par la régie) | U20: à valider
A21: 17 | B21: 46338 | C21: jeudi 12 nov. | D21: 18:00 | E21: TikTok | F21: TOMY | G21: Sketch 25 s | H21: Tempo | I21: Adultes 20 à 45 ans | J21: Fraîcheur de la route | K21: TOFU, se faire connaître | L21: Sketch « Réunion de 8 h » : Tempo menthe noire | M21: Réunion à 8 h, le chef parle de près 😶 | N21: Le collègue qui fait sa présentation trop près... | O21: Réunion à 8 h, le chef parle de près 😶 Tempo, un max de fraîcheur ! Pour toi... ou pour lui 😂 | P21: #Tempo #TOMY #Bureau #225 | Q21: Tague ton collègue | R21: visuels/post17_tempo_video.jpg | S21: =HYPERLINK("https://drive.google.com/file/d/1I424rU6oYYvKwVRc3Tnm2qdxVwH8y5es/view?usp=drivesdk","Voir le visuel 17") | T21: Koffi, Fatima | U21: à valider
A22: 18 | B22: 46339 | C22: vendredi 13 nov. | D22: 19:00 | E22: Instagram | F22: Rio Pop | G22: Reel (reprise TikTok) | H22: Rio Pop Ice Cream | I22: Ados 13 à 17 ans | J22: Couleurs et fun | K22: TOFU, se faire connaître | L22: Reprise ASMR Rio Pop Ice Cream | M22: Monte le son 🔊 | N22: Le déballage le plus satisfaisant de Babi. | O22: Monte le son 🔊🍦 Rio Pop Ice Cream : le papier, le craquant, puis le chewing-gum. | P22: #RioPop #RienNteStop #TOMY #ASMR #Abidjan #225 #Babi #Sucette | Q22: Partage en story | R22: visuels/post18_icecream.jpg | S22: =HYPERLINK("https://drive.google.com/file/d/1HMVWAcY24aG6VXK0v_18u1sWLhUrpDta/view?usp=drivesdk","Voir le visuel 18") | T22: Prisca Yao | U22: à valider
A23: 19 | B23: 46340 | C23: samedi 14 nov. | D23: 12:30 | E23: Facebook | F23: Unifood | G23: Post photo | H23: Unifood (groupe) | I23: Tous | J23: Coulisses qualité | K23: MOFU, faire considérer | L23: Coulisses : le contrôle qualité quotidien au laboratoire interne | M23: Chaque jour, nos bonbons passent par le labo avant de partir. | N23: Depuis 1994, à Koumassi. | O23: Chaque jour, avant de quitter l'usine de Koumassi, nos bonbons passent par notre laboratoire interne. 🔬 Qualité constante, depuis 1994. Quelle question aimeriez-vous poser à notre équipe qualité ? 👇 | P23: #Unifood #TOMY #MadeInCI | Q23: Posez votre question | R23: visuels/post19_qualite.jpg | S23: =HYPERLINK("https://drive.google.com/file/d/1rF8_LFQSx3CdKjm65uH3D-tbJZKWg2sJ/view?usp=drivesdk","Voir le visuel 19") | T23: Fatima (texte), photo du labo ⟦à faire valider par la direction⟧ | U23: à valider
A24: 20 | B24: 46341 | C24: dimanche 15 nov. | D24: 09:00 | E24: Facebook | F24: Unifood | G24: Visuel sobre | H24: Unifood (groupe) | I24: Tous | J24: Temps fort | K24: TOFU, se faire connaître | L24: Journée nationale de la Paix (sans produit, sans prix) | M24: En ce 15 novembre, Unifood souhaite à tous une belle Journée nationale de la Paix. | O24: En ce 15 novembre, toute l'équipe Unifood souhaite à chacun une belle Journée nationale de la Paix. 🕊️🇨🇮 | P24: #JournéeDeLaPaix #CôteDIvoire | Q24: Aucun | R24: visuels/post20_paix.jpg | S24: =HYPERLINK("https://drive.google.com/file/d/1D2bFT0S1Gfl6M6lWDUyCLtWM90BeLVKf/view?usp=drivesdk","Voir le visuel 20") | T24: Prisca Yao (validation de Mariam Koné) | U24: à valider
A25: 21 | B25: 46341 | C25: dimanche 15 nov. | D25: 09:00 | E25: Instagram | F25: Rio Pop | G25: Visuel sobre | H25: Unifood (groupe) | I25: Tous | J25: Temps fort | K25: TOFU, se faire connaître | L25: Journée nationale de la Paix (même visuel) | M25: Belle Journée nationale de la Paix 🕊️ | O25: Belle Journée nationale de la Paix à toutes et à tous. 🕊️🇨🇮 | P25: #JournéeDeLaPaix #CôteDIvoire #Paix #225 | Q25: Aucun | R25: visuels/post21_paix.jpg | S25: =HYPERLINK("https://drive.google.com/file/d/1lo4RH5QEcrCEAbPC3MCo44U0Ih7yEHB7/view?usp=drivesdk","Voir le visuel 21") | T25: Prisca Yao | U25: à valider
A26: 22 | B26: 46342 | C26: lundi 16 nov. | D26: 18:00 | E26: TikTok | F26: TOMY | G26: Vidéo 20 s | H26: Rio Pop | I26: 13 à 17 ans | J26: Défi Montre ta langue | K26: TOFU, se faire connaître | L26: Défi en duo : deux parfums, deux langues | M26: Deux sucettes, deux couleurs, une seule langue 🤯 | N26: Mélange deux parfums, montre le résultat. | O26: Deux sucettes, deux couleurs, une seule langue 🤯👅 Tente le mélange et montre le résultat avec #MontreTaLangueRioPop ! | P26: #MontreTaLangueRioPop #RioPop #TOMY #225 | Q26: Fais le défi | R26: visuels/post22_langue.jpg | S26: =HYPERLINK("https://drive.google.com/file/d/11RYKWGuMTqW_3udfgUZChfHZzihBfKUx/view?usp=drivesdk","Voir le visuel 22") | T26: Koffi | U26: à valider
A27: 23 | B27: 46343 | C27: mardi 17 nov. | D27: 12:30 | E27: Facebook | F27: Rio Pop @RioPop225 | G27: Post photo | H27: Rio Pop | I27: Parents 25 à 45 ans | J27: Fêtes et anniversaires | K27: MOFU, faire considérer | L27: Lancement du kit anniversaire Rio Pop sur WhatsApp | M27: Un anniversaire à préparer ? Écrivez-nous sur WhatsApp 🎂 | N27: Le kit fête Rio Pop vous attend sur WhatsApp. | O27: Un anniversaire à préparer ? 🎂🍭 Écrivez-nous sur WhatsApp : on vous envoie nos idées de déco et de goûter Rio Pop, et on vous dit où trouver le sachet de 48 près de chez vous. 👉 Bouton « Envoyer un message » sur la page. | P27: #RioPop #Anniversaire #RienNteStop | Q27: Écrivez-nous sur WhatsApp | R27: visuels/post23_kit_anniv.jpg | S27: =HYPERLINK("https://drive.google.com/file/d/1IRZ77aHhc-4CFru2AGCT3v83K5QoLfoX/view?usp=drivesdk","Voir le visuel 23") | T27: Prisca Yao (réponses WhatsApp) | U27: à valider
A28: 24 | B28: 46343 | C28: mardi 17 nov. | D28: 19:00 | E28: Instagram | F28: Rio Pop | G28: Carrousel 4 images | H28: Rio Pop | I28: Parents 25 à 45 ans | J28: Fêtes et anniversaires | K28: MOFU, faire considérer | L28: Kit anniversaire : 4 idées en images | M28: 4 idées Rio Pop pour un anniversaire réussi 🎂 | N28: L'anniversaire en couleurs, mode d'emploi. | O28: 4 idées Rio Pop pour un anniversaire réussi 🎂 1. Le bouquet de sucettes 2. Le jeu de la langue colorée 3. Les petits sachets surprise 4. La table aux couleurs des parfums Pour recevoir le kit complet, écrivez-nous sur WhatsApp (lien en bio) 💬 | P28: #RioPop #RienNteStop #TOMY #Anniversaire #FêteEnfant #DécoAnniversaire #Abidjan #225 #Babi #Maman | Q28: WhatsApp (lien en bio) | R28: visuels/post24_kit_anniv.jpg | S28: =HYPERLINK("https://drive.google.com/file/d/1XqM5cRb6GyfvFleOOEYWUjTjTJ37vrpD/view?usp=drivesdk","Voir le visuel 24") | T28: Koffi, Prisca Yao | U28: à valider
A29: 25 | B29: 46344 | C29: mercredi 18 nov. | D29: 18:00 | E29: TikTok | F29: TOMY | G29: Sketch 25 s | H29: Super Mint | I29: Adultes 20 à 45 ans | J29: Fraîcheur de la route | K29: TOFU, se faire connaître | L29: Sketch « Le taxi compteur » : le chauffeur qui a tout prévu | M29: Le taxi qui a toujours un Super Mint pour toi 🚕 | N29: Ce chauffeur a tout compris. | O29: Le chauffeur qui a toujours un Super Mint pour ses clients 🚕❄️ Respect au boss ! Ça glace fort. | P29: #SuperMint #TOMY #Taxi #225 | Q29: Tague un chauffeur | R29: visuels/post25_supermint_video.jpg | S29: =HYPERLINK("https://drive.google.com/file/d/1dkX2TBuHfDffDnHWvB6oX2sikGcIWnhf/view?usp=drivesdk","Voir le visuel 25") | T29: Koffi, Fatima | U29: à valider
A30: 26 | B30: 46345 | C30: jeudi 19 nov. | D30: 12:30 | E30: Facebook | F30: Rio Pop @RioPop225 | G30: Post photo | H30: Rio Pop | I30: Parents 25 à 45 ans | J30: Où trouver Rio Pop | K30: BOFU, faire acheter | L30: Rio Pop chez votre boutiquier (présentoir de comptoir) | M30: Vous voyez ce présentoir ? Rio Pop est là 🍭 | N30: Repérez le présentoir rouge chez votre boutiquier. | O30: Vous voyez ce présentoir chez votre boutiquier ? Rio Pop est là ! 🍭 Sachets de 48 ou sucettes à l'unité, demandez vos parfums préférés. Votre boutiquier n'en a pas encore ? Dites-nous votre quartier en commentaire 📍 | P30: #RioPop #RienNteStop | Q30: Demandez à votre boutiquier | R30: visuels/post26_presentoir.jpg | S30: =HYPERLINK("https://drive.google.com/file/d/1L7nxVd5SFVBY--6BLbSeaPzKdhjTWWPa/view?usp=drivesdk","Voir le visuel 26") | T30: Prisca Yao, équipe d'Hervé Gnagne (photos en boutique) | U30: à valider
A31: 27 | B31: 46346 | C31: vendredi 20 nov. | D31: 18:00 | E31: TikTok | F31: TOMY | G31: Vidéo 20 s | H31: Rio Pop | I31: 13 à 17 ans | J31: Couleurs et fun | K31: TOFU, se faire connaître | L31: « Devine le parfum les yeux bandés » (équipe Unifood) | M31: Yeux bandés : il devine le parfum ou pas ? 🙈 | N31: Notre collègue a perdu son pari... | O31: Yeux bandés, une sucette Rio Pop : il devine le parfum ou pas ? 🙈🍭 Reste jusqu'à la fin 😂 | P31: #RioPop #Défi #TOMY #225 | Q31: Devine avant lui | R31: visuels/post27_parfums.jpg | S31: =HYPERLINK("https://drive.google.com/file/d/1NyXYpXmKG2hgOffcoiD_bW2DF5cmKSX0/view?usp=drivesdk","Voir le visuel 27") | T31: Koffi (avec l'équipe Unifood, adultes) | U31: à valider
A32: 28 | B32: 46346 | C32: vendredi 20 nov. | D32: 19:00 | E32: Instagram | F32: Rio Pop | G32: Reel (reprise TikTok) | H32: Rio Pop | I32: Ados 13 à 17 ans | J32: Couleurs et fun | K32: TOFU, se faire connaître | L32: Reprise « Devine le parfum » | M32: Il devine ou pas ? 🙈 | N32: Les yeux bandés, le goût ne ment pas. | O32: Il devine ou pas ? 🙈🍭 Regarde jusqu'au bout et dis-nous ton score en commentaire. | P32: #RioPop #RienNteStop #TOMY #Défi #Abidjan #225 #Babi #Sucette | Q32: Commente ton score | R32: visuels/post28_parfums.jpg | S32: =HYPERLINK("https://drive.google.com/file/d/1ZEX2AehXnhmJIO3P7CfOOZmV562HUETo/view?usp=drivesdk","Voir le visuel 28") | T32: Prisca Yao | U32: à valider
A33: 29 | B33: 46347 | C33: samedi 21 nov. | D33: 12:30 | E33: Facebook | F33: Unifood | G33: Post photo | H33: Menthes TOMY | I33: Boutiquiers et demi-grossistes | J33: Où trouver Rio Pop | K33: BOFU, faire acheter | L33: Boutiquiers : le catalogue WhatsApp TOMY est ouvert | M33: Boutiquiers : commandez TOMY en 3 messages sur WhatsApp 📲 | N33: Votre stock de fêtes, sans vous déplacer. | O33: Boutiquiers, demi-grossistes : le catalogue TOMY est sur WhatsApp ! 📲 Rio Pop, Super Mint, Tempo, Super Gnamakou : choisissez, envoyez, notre équipe commerciale vous rappelle. 👉 Écrivez « CATALOGUE » au ⟦numéro WhatsApp commercial à confirmer⟧ | P33: #TOMY #Unifood | Q33: Écrivez « CATALOGUE » | R33: visuels/post29_catalogue.jpg | S33: =HYPERLINK("https://drive.google.com/file/d/1edjylv3tHzp83pnAiyAPokxc0cS-x7Q1/view?usp=drivesdk","Voir le visuel 29") | T33: Équipe d'Hervé Gnagne (réponses), Prisca Yao | U33: à compléter le jour même
A34: 30 | B34: 46348 | C34: dimanche 22 nov. | D34: 16:00 | E34: Facebook | F34: Rio Pop @RioPop225 | G34: Post photo | H34: Rio Pop | I34: Parents 25 à 45 ans | J34: Fêtes et anniversaires | K34: MOFU, faire considérer | L34: Idées goûter n°2 : le goûter du dimanche en famille | M34: Dimanche, tout le monde à table, même les sucettes 🍭 | N34: Le dessert du dimanche version Rio Pop. | O34: Dimanche, tout le monde à table, même les sucettes ! 🍭 Fruits coupés, un verre de bissap et une Rio Pop pour finir : le goûter du dimanche est prêt. Votre goûter du dimanche, c'est quoi ? 👇 | P34: #RioPop #Goûter #Famille | Q34: Racontez en commentaire | R34: visuels/post30_gouter.jpg | S34: =HYPERLINK("https://drive.google.com/file/d/1J5sPJFJSTSv-tg2NIDW8nM1x7io4Xamo/view?usp=drivesdk","Voir le visuel 30") | T34: Koffi, Prisca Yao | U34: à valider
A35: 31 | B35: 46349 | C35: lundi 23 nov. | D35: 18:00 | E35: TikTok | F35: TOMY | G35: Vidéo 20 s | H35: Rio Pop | I35: 13 à 17 ans | J35: Défi Montre ta langue | K35: TOFU, se faire connaître | L35: Le défi en version fêtes : langue aux couleurs de Noël | M35: Rouge et vert pour Noël ? Ta langue est prête 🎄 | N35: Le défi passe en mode fêtes ! | O35: Rouge et vert pour Noël ? Ta langue est prête 🎄👅 #MontreTaLangueRioPop passe en mode fêtes ! | P35: #MontreTaLangueRioPop #RioPop #Noël #225 | Q35: Fais le défi | R35: visuels/post31_langue_noel.jpg | S35: =HYPERLINK("https://drive.google.com/file/d/11VqlC89qb-5f1TBnWB7BcsXh-UGr0n63/view?usp=drivesdk","Voir le visuel 31") | T35: Koffi | U35: à valider
A36: 32 | B36: 46350 | C36: mardi 24 nov. | D36: 12:30 | E36: Facebook | F36: Rio Pop @RioPop225 | G36: Carrousel 3 images | H36: Rio Pop | I36: Parents 25 à 45 ans | J36: Fêtes et anniversaires | K36: MOFU, faire considérer | L36: Déco de fête n°2 : le sapin de sucettes | M36: Cette année, le sapin se mange 🎄🍭 | N36: Le sapin qui plaît vraiment aux enfants. | O36: Cette année, le sapin se mange ! 🎄🍭 Un cône en carton, du papier vert, et vos sucettes Rio Pop piquées tout autour. Étapes en images 👉 Pour le kit fête complet : écrivez-nous sur WhatsApp 💬 | P36: #RioPop #Noël #DécoDeFête | Q36: Écrivez-nous sur WhatsApp | R36: visuels/post32_sapin.jpg | S36: =HYPERLINK("https://drive.google.com/file/d/1aIn3AK4RW_CSF04honXQJwjaYx4di5x-/view?usp=drivesdk","Voir le visuel 32") | T36: Koffi (photos), Prisca Yao | U36: à valider
A37: 33 | B37: 46350 | C37: mardi 24 nov. | D37: 19:00 | E37: Instagram | F37: Rio Pop | G37: Reel tuto 30 s | H37: Rio Pop | I37: Parents 25 à 45 ans | J37: Fêtes et anniversaires | K37: MOFU, faire considérer | L37: Tuto du sapin de sucettes | M37: Le sapin de sucettes en 30 secondes 🎄 | N37: DIY de Noël, version Rio Pop. | O37: Le sapin de sucettes en 30 secondes 🎄🍭 📌 Enregistre pour le faire avec les enfants ce week-end ! | P37: #RioPop #RienNteStop #TOMY #Noël #DIY #DécoNoël #Abidjan #225 #Babi #Maman | Q37: Enregistrez | R37: visuels/post33_sapin.jpg | S37: =HYPERLINK("https://drive.google.com/file/d/1p3PXqhtlAqDEzXR0ubaNdSUIKrKwpB3k/view?usp=drivesdk","Voir le visuel 33") | T37: Koffi | U37: à valider
A38: 34 | B38: 46351 | C38: mercredi 25 nov. | D38: 18:00 | E38: TikTok | F38: TOMY | G38: Sketch 25 s | H38: Super Gnamakou | I38: Adultes 20 à 45 ans | J38: Fraîcheur de la route | K38: TOFU, se faire connaître | L38: Sketch « Le froid de l'harmattan arrive » : Gnamakou qui réchauffe | M38: L'harmattan arrive, le Gnamakou aussi 🔥 | N38: Il fait frais le matin ? On a ce qu'il faut. | O38: Les matins deviennent frais ? Super Gnamakou réchauffe 🔥 Ça chauffe grave ! | P38: #SuperGnamakou #TOMY #225 | Q38: Dis « 🔥 » en commentaire | R38: visuels/post34_gnamakou_video.jpg | S38: =HYPERLINK("https://drive.google.com/file/d/15ghRntrGIpwnVvP35WJRN71V2jolNKFk/view?usp=drivesdk","Voir le visuel 34") | T38: Koffi, Fatima | U38: à valider
A39: 35 | B39: 46352 | C39: jeudi 26 nov. | D39: 12:30 | E39: Facebook | F39: Rio Pop @RioPop225 | G39: Post photo | H39: Rio Pop | I39: Parents 25 à 45 ans | J39: Où trouver Rio Pop | K39: BOFU, faire acheter | L39: Le sachet de 48 pour les fêtes : à prévoir avant décembre | M39: Les fêtes approchent : vous avez prévu votre sachet de 48 ? 🎉 | N39: 48 sucettes, toute la famille servie. | O39: Les fêtes approchent : vous avez prévu votre sachet de 48 ? 🎉🍭 De quoi servir tous les cousins au réveillon. Disponible chez votre boutiquier : demandez Rio Pop ! | P39: #RioPop #RienNteStop #Fêtes2026 | Q39: Demandez à votre boutiquier | R39: visuels/post35_sachet48_jaune.jpg | S39: =HYPERLINK("https://drive.google.com/file/d/1jvk0x7UYvKk6hd4gc9JAvboN1xz1MECp/view?usp=drivesdk","Voir le visuel 35") | T39: Prisca Yao | U39: à valider
A40: 36 | B40: 46353 | C40: vendredi 27 nov. | D40: 18:00 | E40: TikTok | F40: TOMY | G40: Vidéo 15 s | H40: Rio Pop | I40: 13 à 17 ans | J40: Couleurs et fun | K40: TOFU, se faire connaître | L40: Tendance du moment adaptée à Rio Pop ⟦son et format à choisir le jour même, idée à vérifier⟧ | M40: ⟦accroche selon la tendance retenue⟧ | O40: ⟦légende écrite le jour même, selon la tendance TikTok vérifiée (lien et date)⟧ | P40: #RioPop #TOMY #225 | Q40: Selon le format | R40: visuels/post36_famille.jpg | S40: =HYPERLINK("https://drive.google.com/file/d/1Bgk8X9OJfAy29NTB6tTsdTrDKFxvhQjy/view?usp=drivesdk","Voir le visuel 36") | T40: Koffi, Fatima (veille la veille) | U40: à compléter le jour même
...

Sheet Charte
A1: Logo et couleurs de la marque (relevées sur le logo et le site, non fournies par Unifood)
A3: Couleur | B3: Code | C3: Usage
A4: Framboise | B4: #E50046 | C4: principale, logo Unifood
A5: Jaune or | B5: #FAB900 | C5: principale, couronne
A6: Encre | B6: #2B1B22 | C6: texte (proposée)
A7: Orange | B7: #F07E26 | C7: gamme (site)
A8: Violet | B8: #A4539B | C8: gamme (site)
A9: Vert | B9: #67B32E | C9: gamme (site)
A10: Bleu ciel | B10: #61C3D9 | C10: gamme (site)
A11: Bordeaux | B11: #B30A3D | C11: gamme (site)
A13: Polices de travail | B13: Baloo 2 (titres), Nunito (texte) | C13: polices officielles non fournies
A14: Planche logo et couleurs | B14: =HYPERLINK("https://drive.google.com/file/d/1hGwyGVmbMIqFhJTHmG7VhOJUfc683eW1/view?usp=drivesdk","Ouvrir la planche")
A15: Dossier des visuels | B15: =HYPERLINK("https://drive.google.com/drive/folders/1MsJSHwA9hQAyiE5EAV6bfNfsnyzl-JBE","Ouvrir le dossier Drive")

Sheet Vue d'ensemble
A1: Vue d'ensemble (calculée sur l'onglet Calendrier)
A3: Par réseau | B3: Publications
A4: Facebook | B4: =COUNTIF(Calendrier!E5:E45,"Facebook")
A5: Instagram | B5: =COUNTIF(Calendrier!E5:E45,"Instagram")
A6: TikTok | B6: =COUNTIF(Calendrier!E5:E45,"TikTok")
A7: Total | B7: =COUNTA(Calendrier!A5:A45)
A9: Par étage | B9: Publications | C9: Part
A10: TOFU, se faire connaître | B10: =COUNTIF(Calendrier!K5:K45,"TOFU, se faire connaître") | C10: =B10/COUNTA(Calendrier!A5:A45)
A11: MOFU, faire considérer | B11: =COUNTIF(Calendrier!K5:K45,"MOFU, faire considérer") | C11: =B11/COUNTA(Calendrier!A5:A45)
A12: BOFU, faire acheter | B12: =COUNTIF(Calendrier!K5:K45,"BOFU, faire acheter") | C12: =B12/COUNTA(Calendrier!A5:A45)
A14: Par gamme | B14: Publications
A15: Menthes TOMY | B15: =COUNTIF(Calendrier!H5:H45,"Menthes TOMY")
A16: Rio Pop | B16: =COUNTIF(Calendrier!H5:H45,"Rio Pop")
A17: Rio Pop Ice Cream | B17: =COUNTIF(Calendrier!H5:H45,"Rio Pop Ice Cream")
A18: Super Gnamakou | B18: =COUNTIF(Calendrier!H5:H45,"Super Gnamakou")
A19: Super Mint | B19: =COUNTIF(Calendrier!H5:H45,"Super Mint")
A20: Tempo | B20: =COUNTIF(Calendrier!H5:H45,"Tempo")
A21: Toutes | B21: =COUNTIF(Calendrier!H5:H45,"Toutes")
A22: Unifood (groupe) | B22: =COUNTIF(Calendrier!H5:H45,"Unifood (groupe)")
A24: Par pilier | B24: Publications
A25: Couleurs et fun | B25: =COUNTIF(Calendrier!J5:J45,"Couleurs et fun")
A26: Coulisses qualité | B26: =COUNTIF(Calendrier!J5:J45,"Coulisses qualité")
A27: Défi Montre ta langue | B27: =COUNTIF(Calendrier!J5:J45,"Défi Montre ta langue")
A28: Fraîcheur de la route | B28: =COUNTIF(Calendrier!J5:J45,"Fraîcheur de la route")
A29: Fêtes et anniversaires | B29: =COUNTIF(Calendrier!J5:J45,"Fêtes et anniversaires")
A30: Où trouver Rio Pop | B30: =COUNTIF(Calendrier!J5:J45,"Où trouver Rio Pop")
A31: Temps fort | B31: =COUNTIF(Calendrier!J5:J45,"Temps fort")
A33: Cadence cible | B33: Facebook 3 à 4 par semaine, Instagram 2 à 3, TikTok 3 (charge tenable : Koffi 2 tournages par semaine, Prisca Yao publication et réponses)
A34: Trous à combler | B34: Aucun post BOFU sur TikTok (normal : 13 à 17 ans, on ne pousse pas l'achat) ; statistiques passées des pages non reliées, donc heures de publication à confirmer après 2 semaines

Sheet Fêtes de novembre
A1: Date | B1: Fête | C1: Type | D1: Date sûre ? | E1: Traitement | F1: Source
A2: 01/11/2026 | B2: Toussaint | C2: Fête fixe, recueillement | D2: oui | E2: Aucun post produit ce jour-là | F2: https://paris.diplomatie.gouv.ci/jours_feries.php (lu le 19/10/2026)
A3: 15/11/2026 | B3: Journée nationale de la Paix (dimanche) | C3: Fête fixe | D3: oui | E3: Visuel sobre, sans produit ni prix | F3: https://allemagne.diplomatie.gouv.ci/jours_feries.php (lu le 19/10/2026)
A4: 16/11/2026 | B4: Lendemain chômé de la Journée de la Paix | C4: Report | D4: à confirmer | E4: Pas de post spécial ; le décret 96-205 ne prévoit le report que pour la fête nationale et le 1er mai | F4: timeanddate.com (lu le 19/10/2026) contre paris.diplomatie.gouv.ci : à vérifier
A5: 25/12/2026 | B5: Noël (préparé dès le 23 nov.) | C5: Fête fixe | D5: oui | E5: Calendrier de décembre | F5: https://paris.diplomatie.gouv.ci/jours_feries.php
